2019-04-23 17:08:01,145 : ERROR : BITMEX: error handling message {"table":"trade","action":"partial","keys":[],"types":{"timestamp":"timestamp","symbol":"symbol","side":"symbol","size":"long","price":"float","tickDirection":"symbol","trdMatchID":"guid","grossValue":"long","homeNotional":"float","foreignNotional":"float"},"foreignKeys":{"symbol":"instrument","side":"side"},"attributes":{"timestamp":"sorted","symbol":"grouped"},"filter":{"symbol":"XBTUSD"},"data":[{"timestamp":"2019-04-23T08:07:18.221Z","symbol":"XBTUSD","side":"Sell","size":9,"price":5540.5,"tickDirection":"ZeroMinusTick","trdMatchID":"be01b8ce-65ab-2d9e-0a2e-11a5334e339d","grossValue":162441,"homeNotional":0.00162441,"foreignNotional":9}]}
2019-04-23 17:08:01,426 : ERROR : BITMEX: encountered an exception, reconnecting
Traceback (most recent call last):
  File "/Users/davidvanisacker/Programming/Trading/backtest/cryptofeed/feedhandler.py", line 163, in _connect
    await self._handler(websocket, feed.message_handler, feed.id)
  File "/Users/davidvanisacker/Programming/Trading/backtest/cryptofeed/feedhandler.py", line 181, in _handler
    await handler(message)
  File "/Users/davidvanisacker/Programming/Trading/backtest/cryptofeed/bitmex/bitmex.py", line 224, in message_handler
    await self._trade(msg)
  File "/Users/davidvanisacker/Programming/Trading/backtest/cryptofeed/bitmex/bitmex.py", line 88, in _trade
    timestamp=data['timestamp'])
  File "/Users/davidvanisacker/Programming/Trading/backtest/cryptofeed/backends/aggregate.py", line 67, in __call__
    if now < self.start_time:
TypeError: '<' not supported between instances of 'float' and 'datetime.datetime'
2019-04-23 17:08:04,413 : ERROR : BITMEX: error handling message {"table":"trade","action":"partial","keys":[],"types":{"timestamp":"timestamp","symbol":"symbol","side":"symbol","size":"long","price":"float","tickDirection":"symbol","trdMatchID":"guid","grossValue":"long","homeNotional":"float","foreignNotional":"float"},"foreignKeys":{"symbol":"instrument","side":"side"},"attributes":{"timestamp":"sorted","symbol":"grouped"},"filter":{"symbol":"XBTUSD"},"data":[{"timestamp":"2019-04-23T08:07:21.841Z","symbol":"XBTUSD","side":"Sell","size":2200,"price":5540.5,"tickDirection":"ZeroMinusTick","trdMatchID":"fbcbf25d-f673-ee19-e6b8-9db7b9cb05ae","grossValue":39707800,"homeNotional":0.397078,"foreignNotional":2200}]}
2019-04-23 17:08:04,720 : ERROR : BITMEX: encountered an exception, reconnecting
Traceback (most recent call last):
  File "/Users/davidvanisacker/Programming/Trading/backtest/cryptofeed/feedhandler.py", line 163, in _connect
    await self._handler(websocket, feed.message_handler, feed.id)
  File "/Users/davidvanisacker/Programming/Trading/backtest/cryptofeed/feedhandler.py", line 181, in _handler
    await handler(message)
  File "/Users/davidvanisacker/Programming/Trading/backtest/cryptofeed/bitmex/bitmex.py", line 224, in message_handler
    await self._trade(msg)
  File "/Users/davidvanisacker/Programming/Trading/backtest/cryptofeed/bitmex/bitmex.py", line 88, in _trade
    timestamp=data['timestamp'])
  File "/Users/davidvanisacker/Programming/Trading/backtest/cryptofeed/backends/aggregate.py", line 67, in __call__
    if now < self.start_time:
TypeError: '<' not supported between instances of 'float' and 'datetime.datetime'
2019-04-23 17:08:44,367 : ERROR : BITMEX: error handling message {"table":"trade","action":"partial","keys":[],"types":{"timestamp":"timestamp","symbol":"symbol","side":"symbol","size":"long","price":"float","tickDirection":"symbol","trdMatchID":"guid","grossValue":"long","homeNotional":"float","foreignNotional":"float"},"foreignKeys":{"symbol":"instrument","side":"side"},"attributes":{"timestamp":"sorted","symbol":"grouped"},"filter":{"symbol":"XBTUSD"},"data":[{"timestamp":"2019-04-23T08:08:02.242Z","symbol":"XBTUSD","side":"Sell","size":58,"price":5539.5,"tickDirection":"ZeroMinusTick","trdMatchID":"bb91a0c7-4be4-b229-7601-9eaa94f753f2","grossValue":1047016,"homeNotional":0.01047016,"foreignNotional":58}]}
2019-04-23 17:08:44,657 : ERROR : BITMEX: encountered an exception, reconnecting
Traceback (most recent call last):
  File "/Users/davidvanisacker/Programming/Trading/backtest/cryptofeed/feedhandler.py", line 163, in _connect
    await self._handler(websocket, feed.message_handler, feed.id)
  File "/Users/davidvanisacker/Programming/Trading/backtest/cryptofeed/feedhandler.py", line 181, in _handler
    await handler(message)
  File "/Users/davidvanisacker/Programming/Trading/backtest/cryptofeed/bitmex/bitmex.py", line 224, in message_handler
    await self._trade(msg)
  File "/Users/davidvanisacker/Programming/Trading/backtest/cryptofeed/bitmex/bitmex.py", line 88, in _trade
    timestamp=data['timestamp'])
  File "/Users/davidvanisacker/Programming/Trading/backtest/cryptofeed/backends/aggregate.py", line 65, in __call__
    now = datetime.time()
TypeError: descriptor 'time' of 'datetime.datetime' object needs an argument
